{"sid": "a71134c9dd93468a8f65b7e0dd011ec6", "uid": null, "qid": "c4243dbdd52c4151a1e199ab7bfee952", "rid": null, "bars": {"default": {"percent": "100", "remaining": "0"}}, "messages": [{"type": "ERROR", "content": "process - failed executing: [c4243dbdd52c4151a1e199ab7bfee952]\nTraceback (most recent call last):\n  File \"/pysdk/.venv/lib/python3.8/site-packages/openfabric_pysdk/app/execution/action_dispatcher.py\", line 139, in process\n    output = self.workerContext.execution.execute(data, self.ray, self.state, update)\n  File \"/pysdk/.venv/lib/python3.8/site-packages/openfabric_pysdk/app/execution/application_interface.py\", line 66, in execute\n    self.execution_function(model)\n  File \"/openfabric/app/main.py\", line 88, in execute\n    agent = Agent('gemini',session_id)\n  File \"/openfabric/app/Agent/agent.py\", line 44, in __init__\n    self.init_baseLLM()\n  File \"/openfabric/app/Agent/agent.py\", line 71, in init_baseLLM\n    self.llm:LLM = GeminiLLM()\n  File \"/openfabric/app/Agent/LLM/Gemini.py\", line 11, in __init__\n    self.client = genai.Client(api_key='AIzaSyCt4xwCe7rolx-7oPh7JOeOHPTT4IquifI')\nAttributeError: module 'google.generativeai' has no attribute 'Client'\n", "created_at": "2025-06-28T07:28:08.494228"}], "status": "FAILED", "created_at": "2025-06-28T07:28:00.950239", "updated_at": "2025-06-28T07:28:08.494264", "finished": true}