{"sid": "1031199bc04b40cebdd74bc0316d25fa", "uid": null, "qid": "42c378be451e47069115e2ee073088d2", "rid": null, "bars": {"default": {"percent": "100", "remaining": "0"}}, "messages": [{"type": "ERROR", "content": "process - failed executing: [42c378be451e47069115e2ee073088d2]\nTraceback (most recent call last):\n  File \"/pysdk/.venv/lib/python3.8/site-packages/openfabric_pysdk/app/execution/action_dispatcher.py\", line 139, in process\n    output = self.workerContext.execution.execute(data, self.ray, self.state, update)\n  File \"/pysdk/.venv/lib/python3.8/site-packages/openfabric_pysdk/app/execution/application_interface.py\", line 66, in execute\n    self.execution_function(model)\n  File \"/openfabric/app/main.py\", line 92, in execute\n    msg , img , obj , sessid  = agent.Exec(user_prompt)\n  File \"/openfabric/app/Agent/agent.py\", line 81, in Exec\n    self.EXIT()\n  File \"/openfabric/app/Agent/agent.py\", line 101, in EXIT\n    Agent.db.save_session(self.session_id,self.username,self.image_desc,Agent.sessions[self.session_id])\n  File \"/openfabric/app/Agent/Storage/VectorDB.py\", line 91, in save_session\n    self.save(session_id=session_id ,username = username ,image_desc=image_desc)\nTypeError: save() got an unexpected keyword argument 'image_desc'\n", "created_at": "2025-06-29T13:06:29.187865"}], "status": "FAILED", "created_at": "2025-06-29T13:06:15.796589", "updated_at": "2025-06-29T13:06:29.187899", "finished": true}