{"sid": "7291b690f846451c81cf469c8e92ef8c", "uid": null, "qid": "f9ed8f54e24e4b38a571d41cd3b309ca", "rid": null, "bars": {"default": {"percent": "100", "remaining": "0"}}, "messages": [{"type": "ERROR", "content": "process - failed executing: [f9ed8f54e24e4b38a571d41cd3b309ca]\nTraceback (most recent call last):\n  File \"/pysdk/.venv/lib/python3.8/site-packages/openfabric_pysdk/app/execution/action_dispatcher.py\", line 139, in process\n    output = self.workerContext.execution.execute(data, self.ray, self.state, update)\n  File \"/pysdk/.venv/lib/python3.8/site-packages/openfabric_pysdk/app/execution/application_interface.py\", line 66, in execute\n    self.execution_function(model)\n  File \"/openfabric/app/main.py\", line 92, in execute\n    msg , img , obj , sessid  = agent.Exec(user_prompt)\n  File \"/openfabric/app/Agent/agent.py\", line 83, in Exec\n    self.EXIT()\n  File \"/openfabric/app/Agent/agent.py\", line 102, in EXIT\n    Agent.db.save_session(self.session_id,self.username,self.exit_summary,Agent.sessions[self.session_id])\n  File \"/openfabric/app/Agent/Storage/VectorDB.py\", line 61, in save_session\n    VectorDB.sessions.insert_one({\"_id\":session_id, \"text\": text,\"summary\":summary})\n  File \"/pysdk/.venv/lib/python3.8/site-packages/pymongo/synchronous/collection.py\", line 891, in insert_one\n    self._insert_one(\n  File \"/pysdk/.venv/lib/python3.8/site-packages/pymongo/synchronous/collection.py\", line 831, in _insert_one\n    self._database.client._retryable_write(\n  File \"/pysdk/.venv/lib/python3.8/site-packages/pymongo/synchronous/mongo_client.py\", line 1898, in _retryable_write\n    return self._retry_with_session(retryable, func, s, bulk, operation, operation_id)\n  File \"/pysdk/.venv/lib/python3.8/site-packages/pymongo/synchronous/mongo_client.py\", line 1784, in _retry_with_session\n    return self._retry_internal(\n  File \"/pysdk/.venv/lib/python3.8/site-packages/pymongo/_csot.py\", line 119, in csot_wrapper\n    return func(self, *args, **kwargs)\n  File \"/pysdk/.venv/lib/python3.8/site-packages/pymongo/synchronous/mongo_client.py\", line 1819, in _retry_internal\n    return _ClientConnectionRetryable(\n  File \"/pysdk/.venv/lib/python3.8/site-packages/pymongo/synchronous/mongo_client.py\", line 2554, in run\n    return self._read() if self._is_read else self._write()\n  File \"/pysdk/.venv/lib/python3.8/site-packages/pymongo/synchronous/mongo_client.py\", line 2676, in _write\n    return self._func(self._session, conn, self._retryable)  # type: ignore\n  File \"/pysdk/.venv/lib/python3.8/site-packages/pymongo/synchronous/collection.py\", line 829, in _insert_command\n    _check_write_command_response(result)\n  File \"/pysdk/.venv/lib/python3.8/site-packages/pymongo/helpers_shared.py\", line 285, in _check_write_command_response\n    _raise_last_write_error(write_errors)\n  File \"/pysdk/.venv/lib/python3.8/site-packages/pymongo/helpers_shared.py\", line 255, in _raise_last_write_error\n    raise DuplicateKeyError(error.get(\"errmsg\"), 11000, error)\npymongo.errors.DuplicateKeyError: E11000 duplicate key error collection: mydb.sessions index: _id_ dup key: { _id: \"e136ffd3-bac4-4e66-8465-d0bd08fac8cf\" }, full error: {'index': 0, 'code': 11000, 'errmsg': 'E11000 duplicate key error collection: mydb.sessions index: _id_ dup key: { _id: \"e136ffd3-bac4-4e66-8465-d0bd08fac8cf\" }', 'keyPattern': {'_id': 1}, 'keyValue': {'_id': 'e136ffd3-bac4-4e66-8465-d0bd08fac8cf'}}\n", "created_at": "2025-06-29T07:06:00.892726"}], "status": "FAILED", "created_at": "2025-06-29T07:05:55.776493", "updated_at": "2025-06-29T07:06:00.892745", "finished": true}