{"sid": "3102c2fcb5e04cc2b6925cb27ee2ca3e", "uid": null, "qid": "d310fe898a294a4c9e2f2bbbb8c8b362", "rid": null, "bars": {"default": {"percent": "100", "remaining": "0"}}, "messages": [{"type": "ERROR", "content": "process - failed executing: [d310fe898a294a4c9e2f2bbbb8c8b362]\nTraceback (most recent call last):\n  File \"/pysdk/.venv/lib/python3.8/site-packages/openfabric_pysdk/app/execution/action_dispatcher.py\", line 139, in process\n    output = self.workerContext.execution.execute(data, self.ray, self.state, update)\n  File \"/pysdk/.venv/lib/python3.8/site-packages/openfabric_pysdk/app/execution/application_interface.py\", line 66, in execute\n    self.execution_function(model)\n  File \"/openfabric/app/main.py\", line 92, in execute\n    agent = Agent('gemini',\"TEST_USER\",session_id ,generator)\n  File \"/openfabric/app/Agent/agent.py\", line 38, in __init__\n    self.init_baseLLM(baseLLM)\n  File \"/openfabric/app/Agent/agent.py\", line 47, in init_baseLLM\n    history.append(Agent._promptManager.get('BasePrompt'))\n  File \"/openfabric/app/Agent/agent.py\", line 213, in get\n    return cls._prompts(key)\nTypeError: 'dict' object is not callable\n", "created_at": "2025-06-30T10:27:35.643583"}], "status": "FAILED", "created_at": "2025-06-30T10:27:33.143802", "updated_at": "2025-06-30T10:27:35.643599", "finished": true}