{"sid": "fa85727bfff34f2593f6dbed53f19e80", "uid": null, "qid": "038b394e5be54886824329bb31751153", "rid": null, "bars": {"default": {"percent": "100", "remaining": "0"}}, "messages": [{"type": "ERROR", "content": "process - failed executing: [038b394e5be54886824329bb31751153]\nTraceback (most recent call last):\n  File \"/pysdk/.venv/lib/python3.8/site-packages/openfabric_pysdk/app/execution/action_dispatcher.py\", line 139, in process\n    output = self.workerContext.execution.execute(data, self.ray, self.state, update)\n  File \"/pysdk/.venv/lib/python3.8/site-packages/openfabric_pysdk/app/execution/application_interface.py\", line 66, in execute\n    self.execution_function(model)\n  File \"/openfabric/app/main.py\", line 61, in execute\n    object = stub.call('c25dcd829d134ea98f5ae4dd311d13bc.node3.openfabric.network', {'prompt':prompt}, 'super-user')\n  File \"/openfabric/app/core/stub.py\", line 85, in call\n    raise Exception(f\"Connection not found for app ID: {app_id}\")\nException: Connection not found for app ID: c25dcd829d134ea98f5ae4dd311d13bc.node3.openfabric.network\n", "created_at": "2025-06-25T10:14:44.105221"}], "status": "FAILED", "created_at": "2025-06-25T10:14:28.056818", "updated_at": "2025-06-25T10:14:44.105244", "finished": true}